Workbook

Sheet Règles FEAMPA
A1: ÉLIGIBILITÉ FEAMPA — RÈGLES GÉNÉRALES
A2: Règles : coûts simplifiés obligatoires au FEAMPA 2021-2027 — salaire au réel (1 607 h), forfait de 15 % des frais de personnel pour les coûts indirects, forfait de 6,3 % des frais de personnel pour les frais de mission (déplacements, hébergement, repas). Toute dépense déclarée au réel doit en outre remplir les conditions générales C1 à C9 ci-dessous. Sources secondaires (DOMO FEAMPA, guides régionaux) : à confirmer avec le service instructeur Occitanie.
A3: CONDITIONS GÉNÉRALES — valables pour toute dépense déclarée au réel
A4: Condition | D4: Ce qu’elle impose | E4: Pièce justificative | F4: Source
A5: C1 — Lien direct avec l’opération | D5: La dépense est nécessaire à l'opération, prévue dans le plan de financement déposé et rattachable à une de ses actions. | E5: Plan de financement, ordre du jour, compte rendu, livrable | F5: Décret n° 2022-608 du 21 avril 2022 ; règlement (UE) 2021/1060 (RPDC)
A6: C2 — Période d’éligibilité | D6: Engagée et payée entre la date de début d'éligibilité (en général le dépôt du dossier complet) et la date de fin fixée par la convention. Aucune dépense antérieure au dépôt. | E6: Accusé de réception du dossier, dates des factures et des paiements | F6: Décret n° 2022-608 du 21 avril 2022 ; règlement (UE) 2021/1060 (RPDC)
A7: C3 — Supportée par le bénéficiaire | D7: Facturée au nom de l'association et payée par elle ; le temps ou les biens payés par une autre entité ne sont pas éligibles (d'où les refacturations). | E7: Facture au nom de l’association, relevé bancaire | F7: Décret n° 2022-608 du 21 avril 2022 ; règlement (UE) 2021/1060 (RPDC)
A8: C4 — Prix raisonnable | D8: Devis ou mise en concurrence selon les seuils de l'autorité de gestion (à confirmer). Si l'association est financée majoritairement sur fonds publics, elle peut relever de la commande publique (à vérifier avec FIDAL). | E8: Devis comparatifs, note de choix | F8: Décret n° 2022-608 du 21 avril 2022 ; règlement (UE) 2021/1060 (RPDC)
A9: C5 — Pas de double financement | D9: Une même dépense ne peut être financée deux fois (autre fonds européen, autre aide, refacturation). Le temps refacturé au fonds et à Mare Services est exclu de l'assiette. | E9: Plan de financement, attestation sur l’honneur | F9: Décret n° 2022-608 du 21 avril 2022 ; règlement (UE) 2021/1060 (RPDC)
A10: C6 — Coûts simplifiés | D10: Frais de structure : forfait de 15 % ; frais de mission : forfait de 6,3 % — les deux obligatoires, jamais au réel. La part des coûts réels au-delà des forfaits est supportée par le fonds de dotation. | E10: Onglet « Contrôle forfaits » | F10: Décret n° 2022-608 du 21 avril 2022 ; règlement (UE) 2021/1060 (RPDC)
A11: C7 — TVA | D11: Éligible seulement si elle n'est pas récupérable (association non assujettie). | E11: Attestation de non-récupération de la TVA | F11: Décret n° 2022-608 du 21 avril 2022 ; règlement (UE) 2021/1060 (RPDC)
A12: C8 — Traçabilité et conservation | D12: Codification comptable propre à l'opération ; pièces conservées 5 ans à compter du 31 décembre de l'année du dernier paiement (art. 82 RPDC). | E12: Grand livre analytique, archivage | F12: Décret n° 2022-608 du 21 avril 2022 ; règlement (UE) 2021/1060 (RPDC)
A13: C9 — Publicité | D13: Logo UE et mention du soutien du FEAMPA sur les supports et le site ; affiche dans les locaux (art. 50 RPDC). Un manquement peut réduire l'aide. | E13: Captures du site, exemplaires, photo de l’affiche | F13: Décret n° 2022-608 du 21 avril 2022 ; règlement (UE) 2021/1060 (RPDC)
A15: Le statut FEAMPA de chaque dépense, ses conditions et les prestataires chiffrés figurent en face de chaque sous-poste, onglet « Hypothèses » (colonnes G à J).

Sheet Hypothèses
A1: BUDGET DE FONCTIONNEMENT PLURIANNUEL 2026-2029
A2: Structure de gouvernance et d'animation du projet Mare Durabilis — portée par l'association
A4: Légende
A5: Cellules bleues sur fond jaune | B5: valeurs à saisir ou à valider
A6: Cellules noires | B6: formules — ne pas écraser
A7: Cellules vertes | B7: liens vers un autre onglet
A8: Périmètre | B8: fonctionnement de la gouvernance uniquement — hors budget projets du fonds de dotation
A10: 1. Moyens humains (quotité en ETP par exercice)
A11: Poste | B11: 2026 | C11: 2027 | D11: 2028 | E11: 2029 | F11: Commentaire
A12: Chef de projet | B12: 1 | C12: 1 | D12: 1 | E12: 1 | F12: Poste dédié — 0,60 ETP animation de l’écosystème (dossier public), 0,20 ETP refacturé au fonds, 0,20 ETP refacturé à Mare Services.
A13: Mois d'activité dans l'exercice | B13: 0 | C13: 6 | D13: 12 | E13: 12
A15: 2. Paramètres financiers
A16: Paramètre | B16: Valeur | F16: Commentaire | G16: Statut FEAMPA | H16: Conditions FEAMPA et traitement retenu | I16: Prestataires et prix publics (relevés le 28/09/2026) | J16: Source
A17: Coût annuel chargé — ETP chef de projet | B17: 55000 | F17: Salaire brut chargé, base 2026. 55 000 € retenus (septembre 2026) : coût employeur estimé à 53-55 k€ pour 2 700 € net mensuels. Hors mutuelle et prévoyance, ajoutées ci-dessous. | G17: ✅ Éligible | H17: Éligible au réel si C1-C9 + : contrat de travail et fiche de poste fixant l'affectation (0,60 ETP) ; feuilles de temps mensuelles signées ; bulletins de paie et preuve du paiement des charges. Coût horaire = salaire chargé ÷ 1 607 h. Le temps refacturé au fonds et à Mare Services est exclu. Frais de personnel éligibles : salaire brut, charges patronales et protection sociale complémentaire prévue au contrat (mutuelle, prévoyance). | I17: —
A18: Complémentaire santé — mutuelle Allianz, part employeur (€ par mois) | B18: 70 | F18: Contrat collectif Allianz, 70 € par mois pris en charge à 100 % par l'employeur (minimum légal : 50 %). Frais de personnel éligibles au prorata de la quotité (0,60 ETP).
A19: Prévoyance cadre — incapacité, invalidité, décès, part employeur (€ par mois) | B19: 60 | F19: Contrat collectif classique : décès (capital et rente éducation), incapacité de travail et invalidité, environ 1,75 % du salaire brut (≈ 3 460 € par mois), au-delà du minimum obligatoire des cadres (1,50 % de la tranche 1), financé à 100 % par l'employeur. À ajuster sur devis.
A20: Revalorisation salariale annuelle | B20: 0.02 | F20: Appliquée à partir de 2027.
A21: Indexation des charges externes | B21: 0.02
A22: Frais généraux — taux forfaitaire | B22: 0
A23: Taux d'intervention publique cible | B23: 0.8
A24: Taux d'autofinancement de l'association | B24: 0.01 | F24: Part du budget portée en ressources propres par l'association (cotisations, contributions).
A25: Quotité du chef de projet éligible au FEAMPA | B25: 0.6 | F25: Temps consacré à l'animation de l'écosystème : les 0,20 ETP refacturés au fonds et les 0,20 ETP refacturés à Mare Services sont du temps passé pour une autre entité, exclu de l'assiette.
A26: Forfait FEAMPA de coûts indirects (% des frais de personnel éligibles) | B26: 0.15 | F26: Coût simplifié obligatoire (art. 54 b) RPDC) : couvre loyer, fluides, télécom, assurances, fournitures, banque… qui ne peuvent pas être déclarés au réel. Le coût réel au-delà du forfait est supporté par le fonds de dotation (reste à charge).
A27: Forfait FEAMPA de frais de mission (% des frais de personnel éligibles) | B27: 0.063 | F27: Coût simplifié obligatoire (DOMO FEAMPA) : couvre les frais de déplacement, d'hébergement et de repas du chef de projet, qui ne peuvent plus être déclarés au réel. Le coût réel au-delà du forfait est supporté par le fonds de dotation (reste à charge). À confirmer avec la Région Occitanie.
A28: 3. Répartition des concours publics sollicités
A29: Financeur | B29: Part | F29: Commentaire
A30: FEAMPA | B30: 1 | F30: Fermeture du Fonds en 2027
A31: Région Occitanie | B31: 0
A32: État et agences publiques | B32: 0
A33: Contrôle — la somme des parts doit valoir 100 % | B33: =SUM(B30:B32) -> 1
A35: 4. Détail des charges externes — chaque bloc alimente une ligne de l'onglet Dépenses
A36: Saisir ici, jamais dans l'onglet Dépenses : les lignes de dépenses sont la somme des sous-postes de leur bloc.
A37: Sous-poste | B37: 2026 | C37: 2027 | D37: 2028 | E37: 2029 | F37: Base de calcul et commentaire | G37: Statut FEAMPA | H37: Conditions FEAMPA et traitement retenu | I37: Prestataires et prix publics (relevés le 28/09/2026) | J37: Source
A38: 2.1 Accompagnement juridique → Dépenses ligne 9
A39: FIDAL — mission 1 : statuts et création du fonds | B39: 0 | C39: 0 | D39: 0 | E39: 0 | F39: Engagée en 2026, avant l'existence de l'association : portée par la SATHOAN ou le fonds. À trancher. | G39: ⚠️ Sous conditions | H39: Éligible si C1-C9 + : devis (C4) ; lettre de mission et facture détaillée rattachées à l'opération (statuts, conventions entre entités). Exclus : contentieux, amendes, pénalités. | I39: FIDAL (cabinet retenu par la SATHOAN) : lettre de mission n° 2026-15 du 20/02/2026 — missions 1 et 2 à 16 537,50 € HT chacune ; mission 3 (amorçage des financements, hors contrat 2026) : forfait plafonné à 70 000 € HT au cahier des charges SATHOAN (30 000 € blocs 1-2, 40 000 € bloc 3) ; taux horaire à demander pour le conseil courant · Comparaison : Adequatio Avocats : 200 € HT/h · Artemisia Lawyers : 300 € HT/h (associations) · Captain Contrat : abonnement 50 à 150 € HT/mois | J39: Lettre de mission FIDAL n° 2026-15 ; cahier des charges SATHOAN 2026 · https://www.adequatio-avocats.fr/honoraires/
A40: FIDAL — mission 2 : cadre applicatif et gouvernance des start-up | B40: 0 | C40: 0 | D40: 0 | E40: 0 | F40: Forfait de mission.
A41: FIDAL — mission 3 : convention de prestation et moyens partagés | B41: 0 | C41: 0 | D41: 0 | E41: 0 | F41: Forfait de mission.
A42: Conseil juridique courant (conventions, bail, contrats) | B42: 0 | C42: 15000 | D42: 25000 | E42: 25000 | F42: Forfait de mission.
A43: Formalités, greffe et publications légales | B43: 0 | C43: 230 | D43: 0 | E43: 0 | F43: Une seule fois, en 2027. Déclaration de création et publication au JOAFE gratuites ; provision pour une modification statutaire par un prestataire en ligne (49 à 189 € HT, soit environ 230 € TTC au plus haut). Coût de structure : couvert par le forfait de 15 %. | G43: 🔸 Forfait 15 % | H43: Non déclarable au réel : coût de structure couvert par le forfait de 15 %. | I43: Publication au JOAFE : gratuite · Legalstart, modification de statuts : 49 à 189 € HT · Retenu : 230 € TTC une seule fois, en 2027 | J43: https://www.service-public.gouv.fr/particuliers/vosdroits/F1119
A45: 2.2 Accompagnement stratégique et financier → Dépenses ligne 10
...

Sheet Dépenses
A1: DÉPENSES DE FONCTIONNEMENT 2026-2029
A2: Aucune saisie sur cette feuille : chaque ligne est la somme des sous-postes de l'onglet Hypothèses.
A3: Poste de dépense | B3: 2026 | C3: 2027 | D3: 2028 | E3: 2029 | F3: Total
A4: 1. CHARGES DE PERSONNEL
A5: Chef de projet | B5: =Hypothèses!B12*Hypothèses!$B$17*(1+Hypothèses!$B$20)^0*Hypothèses!B13/12 -> 0 | C5: =Hypothèses!C12*Hypothèses!$B$17*(1+Hypothèses!$B$20)^1*Hypothèses!C13/12 -> 28050 | D5: =Hypothèses!D12*Hypothèses!$B$17*(1+Hypothèses!$B$20)^2*Hypothèses!D13/12 -> 57222 | E5: =Hypothèses!E12*Hypothèses!$B$17*(1+Hypothèses!$B$20)^3*Hypothèses!E13/12 -> 58366.44 | F5: =SUM(B5:E5) -> 143638.44
A6: Protection sociale complémentaire du chef de projet (mutuelle Allianz, prévoyance) | B6: =Hypothèses!B12*12*(Hypothèses!$B$18+Hypothèses!$B$19)*Hypothèses!B13/12 -> 0 | C6: =Hypothèses!C12*12*(Hypothèses!$B$18+Hypothèses!$B$19)*Hypothèses!C13/12 -> 780 | D6: =Hypothèses!D12*12*(Hypothèses!$B$18+Hypothèses!$B$19)*Hypothèses!D13/12 -> 1560 | E6: =Hypothèses!E12*12*(Hypothèses!$B$18+Hypothèses!$B$19)*Hypothèses!E13/12 -> 1560 | F6: =SUM(B6:E6) -> 3900
A7: Sous-total charges de personnel | B7: =SUM(B5:B6) -> 0 | C7: =SUM(C5:C6) -> 28830 | D7: =SUM(D5:D6) -> 58782 | E7: =SUM(E5:E6) -> 59926.44 | F7: =SUM(B7:E7) -> 147538.44
A8: 2. PRESTATIONS EXTERNES
A9: Accompagnement juridique | B9: =SUM(Hypothèses!B39:B43) -> 0 | C9: =SUM(Hypothèses!C39:C43) -> 15230 | D9: =SUM(Hypothèses!D39:D43) -> 25000 | E9: =SUM(Hypothèses!E39:E43) -> 25000 | F9: =SUM(B9:E9) -> 65230
A10: Accompagnement stratégique et financier (ingénierie) | B10: =SUM(Hypothèses!B46:B48) -> 0 | C10: =SUM(Hypothèses!C46:C48) -> 0 | D10: =SUM(Hypothèses!D46:D48) -> 0 | E10: =SUM(Hypothèses!E46:E48) -> 0 | F10: =SUM(B10:E10) -> 0
A11: Études et expertises | B11: =SUM(Hypothèses!B51:B51) -> 0 | C11: =SUM(Hypothèses!C51:C51) -> 0 | D11: =SUM(Hypothèses!D51:D51) -> 0 | E11: =SUM(Hypothèses!E51:E51) -> 0 | F11: =SUM(B11:E11) -> 0
A12: Communication, édition, site internet | B12: =SUM(Hypothèses!B54:B59) -> 0 | C12: =SUM(Hypothèses!C54:C59) -> 2115 | D12: =SUM(Hypothèses!D54:D59) -> 1915 | E12: =SUM(Hypothèses!E54:E59) -> 1915 | F12: =SUM(B12:E12) -> 5945
A13: Sous-total prestations externes | B13: =SUM(B9:B12) -> 0 | C13: =SUM(C9:C12) -> 17345 | D13: =SUM(D9:D12) -> 26915 | E13: =SUM(E9:E12) -> 26915 | F13: =SUM(B13:E13) -> 71175
A14: 3. DÉPLACEMENTS ET MISSIONS
A15: Déplacements du chef de projet | B15: =SUM(Hypothèses!B62:B66) -> 0 | C15: =SUM(Hypothèses!C62:C66) -> 4490 | D15: =SUM(Hypothèses!D62:D66) -> 6080 | E15: =SUM(Hypothèses!E62:E66) -> 6080 | F15: =SUM(B15:E15) -> 16650
A16: Frais de mission (hébergement, repas, colloques) | B16: =SUM(Hypothèses!B69:B72) -> 0 | C16: =SUM(Hypothèses!C69:C72) -> 3100 | D16: =SUM(Hypothèses!D69:D72) -> 4600 | E16: =SUM(Hypothèses!E69:E72) -> 4600 | F16: =SUM(B16:E16) -> 12300
A17: Sous-total déplacements et missions | B17: =SUM(B15:B16) -> 0 | C17: =SUM(C15:C16) -> 7590 | D17: =SUM(D15:D16) -> 10680 | E17: =SUM(E15:E16) -> 10680 | F17: =SUM(B17:E17) -> 28950
A18: 4. ANIMATION ET CONCERTATION
A19: Ateliers, réunions de filière, comités | B19: =SUM(Hypothèses!B75:B78) -> 0 | C19: =SUM(Hypothèses!C75:C78) -> 700 | D19: =SUM(Hypothèses!D75:D78) -> 550 | E19: =SUM(Hypothèses!E75:E78) -> 550 | F19: =SUM(B19:E19) -> 1800
A20: Concertation avec les partenaires extérieurs | B20: =SUM(Hypothèses!B81:B81) -> 0 | C20: =SUM(Hypothèses!C81:C81) -> 500 | D20: =SUM(Hypothèses!D81:D81) -> 500 | E20: =SUM(Hypothèses!E81:E81) -> 500 | F20: =SUM(B20:E20) -> 1500
A21: Sous-total animation et concertation | B21: =SUM(B19:B20) -> 0 | C21: =SUM(C19:C20) -> 1200 | D21: =SUM(D19:D20) -> 1050 | E21: =SUM(E19:E20) -> 1050 | F21: =SUM(B21:E21) -> 3300
A22: 5. FRAIS GÉNÉRAUX ET FINANCIERS (locaux et mobilier portés par le fonds de dotation)
A23: Location des locaux — transférée au fonds de dotation (bloc C) | B23: =SUM(Hypothèses!B84:B87) -> 0 | C23: =SUM(Hypothèses!C84:C87) -> 0 | D23: =SUM(Hypothèses!D84:D87) -> 0 | E23: =SUM(Hypothèses!E84:E87) -> 0 | F23: =SUM(B23:E23) -> 0
A24: Charges locatives, fluides et entretien | B24: =SUM(Hypothèses!B90:B93) -> 0 | C24: =SUM(Hypothèses!C90:C93) -> 1200 | D24: =SUM(Hypothèses!D90:D93) -> 1224 | E24: =SUM(Hypothèses!E90:E93) -> 1248 | F24: =SUM(B24:E24) -> 3672
A25: Assurances de l'association | B25: =SUM(Hypothèses!B96:B99) -> 0 | C25: =SUM(Hypothèses!C96:C99) -> 700 | D25: =SUM(Hypothèses!D96:D99) -> 714 | E25: =SUM(Hypothèses!E96:E99) -> 728 | F25: =SUM(B25:E25) -> 2142
A26: Télécommunications, internet et abonnements | B26: =SUM(Hypothèses!B102:B109) -> 0 | C26: =SUM(Hypothèses!C102:C109) -> 2148 | D26: =SUM(Hypothèses!D102:D109) -> 2852 | E26: =SUM(Hypothèses!E102:E109) -> 2909 | F26: =SUM(B26:E26) -> 7909
A27: Fournitures et petit équipement | B27: =SUM(Hypothèses!B112:B121) -> 0 | C27: =SUM(Hypothèses!C112:C121) -> 2550 | D27: =SUM(Hypothèses!D112:D121) -> 2450 | E27: =SUM(Hypothèses!E112:E121) -> 2450 | F27: =SUM(B27:E27) -> 7450
A28: Cotisations, frais bancaires et divers | B28: =SUM(Hypothèses!B124:B127) -> 0 | C28: =SUM(Hypothèses!C124:C127) -> 720 | D28: =SUM(Hypothèses!D124:D127) -> 722 | E28: =SUM(Hypothèses!E124:E127) -> 724 | F28: =SUM(B28:E28) -> 2166
A29: Frais financiers — avance de trésorerie du Crédit Maritime (non éligibles) | B29: =Hypothèses!B129 -> 0 | C29: =Hypothèses!C129 -> 224 | D29: =Hypothèses!D129 -> 2950 | E29: =Hypothèses!E129 -> 12942 | F29: =SUM(B29:E29) -> 16116
A30: Sous-total frais généraux et financiers | B30: =SUM(B23:B29) -> 0 | C30: =SUM(C23:C29) -> 7542 | D30: =SUM(D23:D29) -> 10912 | E30: =SUM(E23:E29) -> 21001 | F30: =SUM(B30:E30) -> 39455
A32: TOTAL DÉPENSES | B32: =B7+B13+B17+B21+B30 -> 0 | C32: =C7+C13+C17+C21+C30 -> 62507 | D32: =D7+D13+D17+D21+D30 -> 108339 | E32: =E7+E13+E17+E21+E30 -> 119572.44 | F32: =SUM(B32:E32) -> 290418.44
A34: Périmètre — ce budget couvre le fonctionnement de la gouvernance. Il ne comprend ni les projets financés par le fonds de dotation, ni les dépenses des structures économiques.
A35: Les locaux et le mobilier sont portés par le fonds de dotation (bloc C) et mis à disposition de l'association par convention. Les autres frais de structure restent à l'association et sont couverts, côté FEAMPA, par le forfait de 15 %.
A38: ASSIETTE ÉLIGIBLE FEAMPA — coûts simplifiés
A39: Chef de projet — part éligible (salaire chargé et protection sociale, quotité hors temps refacturé) | B39: =(B5+B6)*Hypothèses!$B$25 -> 0 | C39: =(C5+C6)*Hypothèses!$B$25 -> 17298 | D39: =(D5+D6)*Hypothèses!$B$25 -> 35269.2 | E39: =(E5+E6)*Hypothèses!$B$25 -> 35955.864 | F39: =SUM(B39:E39) -> 88523.064
A40: Forfait de coûts indirects (15 % des frais de personnel éligibles) | B40: =B39*Hypothèses!$B$26 -> 0 | C40: =C39*Hypothèses!$B$26 -> 2594.7 | D40: =D39*Hypothèses!$B$26 -> 5290.38 | E40: =E39*Hypothèses!$B$26 -> 5393.3796 | F40: =SUM(B40:E40) -> 13278.46
A41: Prestations externes directes (juridique, ingénierie, études, communication), hors frais couverts par le forfait | B41: =B13-Hypothèses!B43-Hypothèses!B54-Hypothèses!B59 -> 0 | C41: =C13-Hypothèses!C43-Hypothèses!C54-Hypothèses!C59 -> 17000 | D41: =D13-Hypothèses!D43-Hypothèses!D54-Hypothèses!D59 -> 26800 | E41: =E13-Hypothèses!E43-Hypothèses!E54-Hypothèses!E59 -> 26800 | F41: =SUM(B41:E41) -> 70600
A42: Forfait de frais de mission (6,3 % des frais de personnel éligibles : déplacements, hébergement, repas) | B42: =B39*Hypothèses!$B$27 -> 0 | C42: =C39*Hypothèses!$B$27 -> 1089.774 | D42: =D39*Hypothèses!$B$27 -> 2221.9596 | E42: =E39*Hypothèses!$B$27 -> 2265.2194 | F42: =SUM(B42:E42) -> 5576.953
A43: Inscriptions à des colloques et salons liés à l’opération (au réel, hors forfait de mission — à confirmer) | B43: =Hypothèses!B72 -> 0 | C43: =Hypothèses!C72 -> 1500 | D43: =Hypothèses!D72 -> 3000 | E43: =Hypothèses!E72 -> 3000 | F43: =SUM(B43:E43) -> 7500
A44: Animation et concertation (réunions de l'opération) | B44: =B21 -> 0 | C44: =C21 -> 1200 | D44: =D21 -> 1050 | E44: =E21 -> 1050 | F44: =SUM(B44:E44) -> 3300
...

Sheet Ressources
A1: PLAN DE FINANCEMENT 2026-2029
A3: Ressource | B3: 2026 | C3: 2027 | D3: 2028 | E3: 2029 | F3: Total
A4: FINANCEMENTS PUBLICS
A5: FEAMPA | B5: =Hypothèses!$B$23*Hypothèses!$B$30*Dépenses!B45 -> 0 | C5: =Hypothèses!$B$23*Hypothèses!$B$30*Dépenses!C45 -> 32545.979 | D5: =Hypothèses!$B$23*Hypothèses!$B$30*Dépenses!D45 -> 58905.232 | E5: =Hypothèses!$B$23*Hypothèses!$B$30*Dépenses!E45 -> 59571.57 | F5: =SUM(B5:E5) -> 151022.78
A6: Région Occitanie | B6: =Hypothèses!$B$23*Hypothèses!$B$31*Dépenses!B45 -> 0 | C6: =Hypothèses!$B$23*Hypothèses!$B$31*Dépenses!C45 -> 0 | D6: =Hypothèses!$B$23*Hypothèses!$B$31*Dépenses!D45 -> 0 | E6: =Hypothèses!$B$23*Hypothèses!$B$31*Dépenses!E45 -> 0 | F6: =SUM(B6:E6) -> 0
A7: État et agences publiques | B7: =Hypothèses!$B$23*Hypothèses!$B$32*Dépenses!B45 -> 0 | C7: =Hypothèses!$B$23*Hypothèses!$B$32*Dépenses!C45 -> 0 | D7: =Hypothèses!$B$23*Hypothèses!$B$32*Dépenses!D45 -> 0 | E7: =Hypothèses!$B$23*Hypothèses!$B$32*Dépenses!E45 -> 0 | F7: =SUM(B7:E7) -> 0
A8: Sous-total financements publics | B8: =SUM(B5:B7) -> 0 | C8: =SUM(C5:C7) -> 32545.979 | D8: =SUM(D5:D7) -> 58905.232 | E8: =SUM(E5:E7) -> 59571.57 | F8: =SUM(B8:E8) -> 151022.78
A9: RESSOURCES PROPRES ET PRIVÉES
A10: Refacturation au fonds de dotation — quote-part du chef de projet (0,20 ETP) | B10: 0 | C10: =0.2*(Dépenses!C5+Dépenses!C6) -> 5766 | D10: =0.2*(Dépenses!D5+Dépenses!D6) -> 11756.4 | E10: =0.2*(Dépenses!E5+Dépenses!E6) -> 11985.288 | F10: =SUM(B10:E10) -> 29507.688
A11: Refacturation au fonds de dotation — quote-part des moyens matériels (20 %) | B11: 0 | C11: =0.2*(Dépenses!C23+Dépenses!C24+Hypothèses!C96+Dépenses!C26+Dépenses!C27-Hypothèses!C113) -> 1239.6 | D11: =0.2*(Dépenses!D23+Dépenses!D24+Hypothèses!D96+Dépenses!D26+Dépenses!D27-Hypothèses!D113) -> 1366.4 | E11: =0.2*(Dépenses!E23+Dépenses!E24+Hypothèses!E96+Dépenses!E26+Dépenses!E27-Hypothèses!E113) -> 1383.8 | F11: =SUM(B11:E11) -> 3989.8
A12: Refacturation à Mare Services — quote-part du chef de projet (0,20 ETP) | B12: 0 | C12: =0.2*(Dépenses!C5+Dépenses!C6) -> 5766 | D12: =0.2*(Dépenses!D5+Dépenses!D6) -> 11756.4 | E12: =0.2*(Dépenses!E5+Dépenses!E6) -> 11985.288 | F12: =SUM(B12:E12) -> 29507.688
A13: Refacturation à Mare Services — quote-part des moyens matériels (20 %) | B13: 0 | C13: =0.2*(Dépenses!C23+Dépenses!C24+Hypothèses!C96+Dépenses!C26+Dépenses!C27-Hypothèses!C113) -> 1239.6 | D13: =0.2*(Dépenses!D23+Dépenses!D24+Hypothèses!D96+Dépenses!D26+Dépenses!D27-Hypothèses!D113) -> 1366.4 | E13: =0.2*(Dépenses!E23+Dépenses!E24+Hypothèses!E96+Dépenses!E26+Dépenses!E27-Hypothèses!E113) -> 1383.8 | F13: =SUM(B13:E13) -> 3989.8
A14: Reste à charge de la part non publique — versé par le fonds de dotation à l'association (bloc B.3) | B14: =MAX(0,Dépenses!B32-B8-B10-B11-B12-B13-B15) -> 0 | C14: =MAX(0,Dépenses!C32-C8-C10-C11-C12-C13-C15) -> 15324.751 | D14: =MAX(0,Dépenses!D32-D8-D10-D11-D12-D13-D15) -> 22104.778 | E14: =MAX(0,Dépenses!E32-E8-E10-E11-E12-E13-E15) -> 32066.969 | F14: =SUM(B14:E14) -> 69496.498
A15: Autofinancement de l'association (1 % des dépenses) | B15: =Hypothèses!$B$24*Dépenses!B32 -> 0 | C15: =Hypothèses!$B$24*Dépenses!C32 -> 625.07 | D15: =Hypothèses!$B$24*Dépenses!D32 -> 1083.39 | E15: =Hypothèses!$B$24*Dépenses!E32 -> 1195.7244 | F15: =SUM(B15:E15) -> 2904.1844
A16: Sous-total ressources propres et privées | B16: =SUM(B10:B15) -> 0 | C16: =SUM(C10:C15) -> 29961.021 | D16: =SUM(D10:D15) -> 49433.768 | E16: =SUM(E10:E15) -> 60000.87 | F16: =SUM(B16:E16) -> 139395.66
A17: TOTAL RESSOURCES | B17: =B8+B16 -> 0 | C17: =C8+C16 -> 62507 | D17: =D8+D16 -> 108339 | E17: =E8+E16 -> 119572.44 | F17: =SUM(B17:E17) -> 290418.44

Sheet Synthèse
A1: SYNTHÈSE 2026-2029
A3: Indicateur | B3: 2026 | C3: 2027 | D3: 2028 | E3: 2029 | F3: Total
A4: Total des dépenses | B4: =Dépenses!B32 -> 0 | C4: =Dépenses!C32 -> 62507 | D4: =Dépenses!D32 -> 108339 | E4: =Dépenses!E32 -> 119572.44 | F4: =SUM(B4:E4) -> 290418.44
A5: Total des ressources | B5: =Ressources!B17 -> 0 | C5: =Ressources!C17 -> 62507 | D5: =Ressources!D17 -> 108339 | E5: =Ressources!E17 -> 119572.44 | F5: =SUM(B5:E5) -> 290418.44
A6: Écart | B6: =B5-B4 -> 0 | C6: =C5-C4 -> 0 | D6: =D5-D4 -> 0 | E6: =E5-E4 -> 0 | F6: =SUM(B6:E6) -> 0
A8: Dont charges de personnel | B8: =Dépenses!B7 -> 0 | C8: =Dépenses!C7 -> 28830 | D8: =Dépenses!D7 -> 58782 | E8: =Dépenses!E7 -> 59926.44 | F8: =SUM(B8:E8) -> 147538.44
A9: Dont prestations externes | B9: =Dépenses!B13 -> 0 | C9: =Dépenses!C13 -> 17345 | D9: =Dépenses!D13 -> 26915 | E9: =Dépenses!E13 -> 26915 | F9: =SUM(B9:E9) -> 71175
A10: Dont déplacements et missions | B10: =Dépenses!B17 -> 0 | C10: =Dépenses!C17 -> 7590 | D10: =Dépenses!D17 -> 10680 | E10: =Dépenses!E17 -> 10680 | F10: =SUM(B10:E10) -> 28950
A11: Dont animation et concertation | B11: =Dépenses!B21 -> 0 | C11: =Dépenses!C21 -> 1200 | D11: =Dépenses!D21 -> 1050 | E11: =Dépenses!E21 -> 1050 | F11: =SUM(B11:E11) -> 3300
A12: Dont frais généraux et financiers (hors locaux et mobilier, portés par le fonds) | B12: =Dépenses!B30 -> 0 | C12: =Dépenses!C30 -> 7542 | D12: =Dépenses!D30 -> 10912 | E12: =Dépenses!E30 -> 21001 | F12: =SUM(B12:E12) -> 39455
A14: Dont financements publics | B14: =Ressources!B8 -> 0 | C14: =Ressources!C8 -> 32545.979 | D14: =Ressources!D8 -> 58905.232 | E14: =Ressources!E8 -> 59571.57 | F14: =SUM(B14:E14) -> 151022.78
A15: Dont refacturations au fonds de dotation (service rendu) | B15: =Ressources!B10+Ressources!B11 -> 0 | C15: =Ressources!C10+Ressources!C11 -> 7005.6 | D15: =Ressources!D10+Ressources!D11 -> 13122.8 | E15: =Ressources!E10+Ressources!E11 -> 13369.088 | F15: =SUM(B15:E15) -> 33497.488
A16: Dont refacturation à Mare Services (0,20 ETP et 20 % des moyens matériels) | B16: =Ressources!B12+Ressources!B13 -> 0 | C16: =Ressources!C12+Ressources!C13 -> 7005.6 | D16: =Ressources!D12+Ressources!D13 -> 13122.8 | E16: =Ressources!E12+Ressources!E13 -> 13369.088 | F16: =SUM(B16:E16) -> 33497.488
A17: Dont reste à charge de la part non publique reçu du fonds de dotation | B17: =Ressources!B14 -> 0 | C17: =Ressources!C14 -> 15324.751 | D17: =Ressources!D14 -> 22104.778 | E17: =Ressources!E14 -> 32066.969 | F17: =SUM(B17:E17) -> 69496.498
A18: Dont autofinancement de l'association | B18: =Ressources!B15 -> 0 | C18: =Ressources!C15 -> 625.07 | D18: =Ressources!D15 -> 1083.39 | E18: =Ressources!E15 -> 1195.7244 | F18: =SUM(B18:E18) -> 2904.1844
A20: Taux de financement public | B20: =IFERROR(B14/B4,0) -> 0 | C20: =IFERROR(C14/C4,0) -> 0.52067735 | D20: =IFERROR(D14/D4,0) -> 0.54371216 | E20: =IFERROR(E14/E4,0) -> 0.49820486 | F20: =IFERROR(F14/F4,0) -> 0.52001788
A21: Part des charges de personnel | B21: =IFERROR(B8/B4,0) -> 0 | C21: =IFERROR(C8/C4,0) -> 0.46122834 | D21: =IFERROR(D8/D4,0) -> 0.5425747 | E21: =IFERROR(E8/E4,0) -> 0.50117268 | F21: =IFERROR(F8/F4,0) -> 0.50802022
A22: Coût annuel moyen de la gouvernance | F22: =IFERROR(F4/3,0) -> 96806.147
A23: Part du budget portée par le fonds de dotation | B23: =IFERROR((B15+B17)/B4,0) -> 0 | C23: =IFERROR((C15+C17)/C4,0) -> 0.3572456 | D23: =IFERROR((D15+D17)/D4,0) -> 0.32516064 | E23: =IFERROR((E15+E17)/E4,0) -> 0.37998771 | F23: =IFERROR((F15+F17)/F4,0) -> 0.35463997

Sheet Contrôle forfaits
A1: CONTRÔLE DES FORFAITS FEAMPA — frais de structure (15 %) et frais de mission (6,3 %)
A2: Les deux forfaits sont obligatoires : ni les frais de structure ni les frais de mission ne peuvent être déclarés au réel. Cet onglet mesure la part des coûts réels couverte par chaque forfait ; le reste est supporté par le fonds de dotation, via le reste à charge versé à l'association (bloc B.3). Aucune saisie : tout est calculé.
A3: Poste | B3: 2026 | C3: 2027 | D3: 2028 | E3: 2029 | F3: Total
A4: A. FORFAIT DE 15 % — FRAIS DE STRUCTURE (coûts indirects, art. 54 b) RPDC)
A5: Frais de personnel directs éligibles — chef de projet, 0,60 ETP | B5: =Dépenses!B39 -> 0 | C5: =Dépenses!C39 -> 17298 | D5: =Dépenses!D39 -> 35269.2 | E5: =Dépenses!E39 -> 35955.864 | F5: =SUM(B5:E5) -> 88523.064
A6: Taux forfaitaire | B6: =Hypothèses!$B$26 -> 0.15 | C6: =Hypothèses!$B$26 -> 0.15 | D6: =Hypothèses!$B$26 -> 0.15 | E6: =Hypothèses!$B$26 -> 0.15
A7: Forfait de 15 % déclaré dans l’assiette | B7: =Dépenses!B40 -> 0 | C7: =Dépenses!C40 -> 2594.7 | D7: =Dépenses!D40 -> 5290.38 | E7: =Dépenses!E40 -> 5393.3796 | F7: =SUM(B7:E7) -> 13278.46
A8: dont aide FEAMPA correspondante (taux d’intervention) | B8: =B7*Hypothèses!$B$23 -> 0 | C8: =C7*Hypothèses!$B$23 -> 2075.76 | D8: =D7*Hypothèses!$B$23 -> 4232.304 | E8: =E7*Hypothèses!$B$23 -> 4314.7037 | F8: =SUM(B8:E8) -> 10622.768
A9: Coûts indirects réels supportés par l’association — non déclarables au réel
A10: Formalités, greffe, publications légales | B10: =N(Hypothèses!B43) -> 0 | C10: =N(Hypothèses!C43) -> 230 | D10: =N(Hypothèses!D43) -> 0 | E10: =N(Hypothèses!E43) -> 0 | F10: =SUM(B10:E10) -> 230
A11: Nom de domaine (refacturé par la SATHOAN) | B11: =Hypothèses!B54 -> 0 | C11: =Hypothèses!C54 -> 15 | D11: =Hypothèses!D54 -> 15 | E11: =Hypothèses!E54 -> 15 | F11: =SUM(B11:E11) -> 45
A12: Abonnements aux outils de diffusion | B12: =Hypothèses!B59 -> 0 | C12: =Hypothèses!C59 -> 100 | D12: =Hypothèses!D59 -> 100 | E12: =Hypothèses!E59 -> 100 | F12: =SUM(B12:E12) -> 300
A13: Charges locatives, fluides et entretien | B13: =Dépenses!B24 -> 0 | C13: =Dépenses!C24 -> 1200 | D13: =Dépenses!D24 -> 1224 | E13: =Dépenses!E24 -> 1248 | F13: =SUM(B13:E13) -> 3672
A14: Assurances de l’association | B14: =Dépenses!B25 -> 0 | C14: =Dépenses!C25 -> 700 | D14: =Dépenses!D25 -> 714 | E14: =Dépenses!E25 -> 728 | F14: =SUM(B14:E14) -> 2142
A15: Télécommunications, internet et abonnements | B15: =Dépenses!B26 -> 0 | C15: =Dépenses!C26 -> 2148 | D15: =Dépenses!D26 -> 2852 | E15: =Dépenses!E26 -> 2909 | F15: =SUM(B15:E15) -> 7909
A16: Fournitures et petit équipement | B16: =Dépenses!B27 -> 0 | C16: =Dépenses!C27 -> 2550 | D16: =Dépenses!D27 -> 2450 | E16: =Dépenses!E27 -> 2450 | F16: =SUM(B16:E16) -> 7450
A17: Cotisations, frais bancaires et divers | B17: =Dépenses!B28 -> 0 | C17: =Dépenses!C28 -> 720 | D17: =Dépenses!D28 -> 722 | E17: =Dépenses!E28 -> 724 | F17: =SUM(B17:E17) -> 2166
A18: Total des frais de structure réels | B18: =SUM(B10:B17) -> 0 | C18: =SUM(C10:C17) -> 7663 | D18: =SUM(D10:D17) -> 8077 | E18: =SUM(E10:E17) -> 8174 | F18: =SUM(B18:E18) -> 23914
A19: Part supportée par le forfait de 15 % | B19: =MIN(B7,B18) -> 0 | C19: =MIN(C7,C18) -> 2594.7 | D19: =MIN(D7,D18) -> 5290.38 | E19: =MIN(E7,E18) -> 5393.3796 | F19: =SUM(B19:E19) -> 13278.46
A20: Reste supporté par le fonds de dotation (reste à charge B.3) | B20: =B18-B19 -> 0 | C20: =C18-C19 -> 5068.3 | D20: =D18-D19 -> 2786.62 | E20: =E18-E19 -> 2780.6204 | F20: =SUM(B20:E20) -> 10635.54
A22: B. FORFAIT DE 6,3 % — FRAIS DE MISSION (déplacements, hébergement, repas du chef de projet)
A23: Taux forfaitaire | B23: =Hypothèses!$B$27 -> 0.063 | C23: =Hypothèses!$B$27 -> 0.063 | D23: =Hypothèses!$B$27 -> 0.063 | E23: =Hypothèses!$B$27 -> 0.063
A24: Forfait de 6,3 % déclaré dans l’assiette | B24: =Dépenses!B42 -> 0 | C24: =Dépenses!C42 -> 1089.774 | D24: =Dépenses!D42 -> 2221.9596 | E24: =Dépenses!E42 -> 2265.2194 | F24: =SUM(B24:E24) -> 5576.953 | G24: 6,3 % des frais de personnel éligibles (ligne 5). Acquis sans justificatif de dépense.
A25: dont aide FEAMPA correspondante (taux d’intervention) | B25: =B24*Hypothèses!$B$23 -> 0 | C25: =C24*Hypothèses!$B$23 -> 871.8192 | D25: =D24*Hypothèses!$B$23 -> 1777.5677 | E25: =E24*Hypothèses!$B$23 -> 1812.1755 | F25: =SUM(B25:E25) -> 4461.5624
A26: Frais de mission réels (véhicule SATHOAN, train, avion, location, stationnement, nuitées, repas) | B26: =Dépenses!B17-Hypothèses!B71-Hypothèses!B72 -> 0 | C26: =Dépenses!C17-Hypothèses!C71-Hypothèses!C72 -> 6090 | D26: =Dépenses!D17-Hypothèses!D71-Hypothèses!D72 -> 7680 | E26: =Dépenses!E17-Hypothèses!E71-Hypothèses!E72 -> 7680 | F26: =SUM(B26:E26) -> 21450 | G26: Hors inscriptions aux colloques (déclarées au réel) et hors frais de représentation (transférés au fonds).
A27: Part supportée par le forfait de 6,3 % | B27: =MIN(B24,B26) -> 0 | C27: =MIN(C24,C26) -> 1089.774 | D27: =MIN(D24,D26) -> 2221.9596 | E27: =MIN(E24,E26) -> 2265.2194 | F27: =SUM(B27:E27) -> 5576.953
A28: Reste supporté par le fonds de dotation (reste à charge B.3) | B28: =B26-B27 -> 0 | C28: =C26-C27 -> 5000.226 | D28: =D26-D27 -> 5458.0404 | E28: =E26-E27 -> 5414.7806 | F28: =SUM(B28:E28) -> 15873.047
A30: C. SYNTHÈSE — FRAIS COUVERTS PAR LES FORFAITS ET PAR LE FONDS
A31: Frais de structure et de mission réels | B31: =B18+B26 -> 0 | C31: =C18+C26 -> 13753 | D31: =D18+D26 -> 15757 | E31: =E18+E26 -> 15854 | F31: =SUM(B31:E31) -> 45364
A32: supportés par les forfaits FEAMPA (15 % et 6,3 %) | B32: =B19+B27 -> 0 | C32: =C19+C27 -> 3684.474 | D32: =D19+D27 -> 7512.3396 | E32: =E19+E27 -> 7658.599 | F32: =SUM(B32:E32) -> 18855.413
A33: supportés par le fonds de dotation | B33: =B20+B28 -> 0 | C33: =C20+C28 -> 10068.526 | D33: =D20+D28 -> 8244.6604 | E33: =E20+E28 -> 8195.401 | F33: =SUM(B33:E33) -> 26508.587
A34: Taux de couverture par les forfaits | B34: =IFERROR(B32/B31,0) -> 0 | C34: =IFERROR(C32/C31,0) -> 0.26790329 | D34: =IFERROR(D32/D31,0) -> 0.47676205 | E34: =IFERROR(E32/E31,0) -> 0.48307046 | F34: =IFERROR(F32/F31,0) -> 0.41564705
A36: D. CONTRÔLES — tous doivent afficher « ok »
A37: Le forfait de 15 % vaut exactement 15 % des frais de personnel éligibles | B37: =IF(ABS(B7-B5*B6)<0.01,"ok","ERREUR") -> ok | C37: =IF(ABS(C7-C5*C6)<0.01,"ok","ERREUR") -> ok | D37: =IF(ABS(D7-D5*D6)<0.01,"ok","ERREUR") -> ok | E37: =IF(ABS(E7-E5*E6)<0.01,"ok","ERREUR") -> ok
A38: Le forfait de 6,3 % vaut exactement 6,3 % des frais de personnel éligibles | B38: =IF(ABS(B24-B5*B23)<0.01,"ok","ERREUR") -> ok | C38: =IF(ABS(C24-C5*C23)<0.01,"ok","ERREUR") -> ok | D38: =IF(ABS(D24-D5*D23)<0.01,"ok","ERREUR") -> ok | E38: =IF(ABS(E24-E5*E23)<0.01,"ok","ERREUR") -> ok
A39: Le salaire déclaré n’excède pas la quotité éligible (0,60 ETP) | B39: =IF(B5<=(Dépenses!B5+Dépenses!B6)*Hypothèses!$B$25+0.01,"ok","ERREUR") -> ok | C39: =IF(C5<=(Dépenses!C5+Dépenses!C6)*Hypothèses!$B$25+0.01,"ok","ERREUR") -> ok | D39: =IF(D5<=(Dépenses!D5+Dépenses!D6)*Hypothèses!$B$25+0.01,"ok","ERREUR") -> ok | E39: =IF(E5<=(Dépenses!E5+Dépenses!E6)*Hypothèses!$B$25+0.01,"ok","ERREUR") -> ok
A40: Aucun frais de structure ni de mission au réel : assiette = personnel + deux forfaits + dépenses directes recalculées | B40: =IF(ABS(Dépenses!B45-B5-B7-B24-(SUM(Hypothèses!B39:B42)+SUM(Hypothèses!B46:B48)+Hypothèses!B51+SUM(Hypothèses!B55:B58)+Hypothèses!B72+SUM(Hypothèses!B75:B78)+Hypothèses!B81))<0.01,"ok","ERREUR") -> ok | C40: =IF(ABS(Dépenses!C45-C5-C7-C24-(SUM(Hypothèses!C39:C42)+SUM(Hypothèses!C46:C48)+Hypothèses!C51+SUM(Hypothèses!C55:C58)+Hypothèses!C72+SUM(Hypothèses!C75:C78)+Hypothèses!C81))<0.01,"ok","ERREUR") -> ok | D40: =IF(ABS(Dépenses!D45-D5-D7-D24-(SUM(Hypothèses!D39:D42)+SUM(Hypothèses!D46:D48)+Hypothèses!D51+SUM(Hypothèses!D55:D58)+Hypothèses!D72+SUM(Hypothèses!D75:D78)+Hypothèses!D81))<0.01,"ok","ERREUR") -> ok | E40: =IF(ABS(Dépenses!E45-E5-E7-E24-(SUM(Hypothèses!E39:E42)+SUM(Hypothèses!E46:E48)+Hypothèses!E51+SUM(Hypothèses!E55:E58)+Hypothèses!E72+SUM(Hypothèses!E75:E78)+Hypothèses!E81))<0.01,"ok","ERREUR") -> ok | G40: Recalcul indépendant depuis Hypothèses : conseil juridique, ingénierie, études, communication directe, colloques, animation.
A41: Contrôle global | B41: =IF(COUNTIF(B37:E40,"ok")=16,"ok","À REVOIR") -> ok

Sheet Trésorerie
A1: PLAN DE TRÉSORERIE DE L'ASSOCIATION — encaissements et décaissements par trimestre
A2: Calculé depuis les onglets Dépenses et Ressources. 2027 : charges et refacturations sur T3-T4 (recrutement au 1er juillet), formalités au T1 ; reste à charge (B.3) versé par quarts, comme au planning du fonds ; aide FEAMPA versée sur demande de paiement semestrielle, après service fait et sur factures acquittées. 2030-2031 : seulement la fin de l'opération 2027-2029 (versements FEAMPA restants et remboursement de l'avance), sans les charges de ces exercices.
A4: HYPOTHÈSES DE TRÉSORERIE | B4: Valeur
A5: Délai entre la fin du semestre justifié et le versement FEAMPA (trimestres) | B5: 8 | C5: Délai constaté : un à deux ans entre la demande de paiement et le versement. Hypothèse retenue : deux ans (8 trimestres), à confirmer avec le service instructeur.
A6: Trésorerie minimale de sécurité | B6: 5000 | C6: Solde plancher maintenu sur le compte ; l'avance est tirée dès que le solde passerait dessous.
A7: Taux annuel de l'avance de trésorerie — Crédit Maritime | B7: 0.05 | C7: À confirmer avec le Crédit Maritime (avance sur subvention adossée à la convention FEAMPA).
A8: Quotité maximale de l'avance (en % de l'aide FEAMPA notifiée) | B8: 0.8 | C8: Ordre de grandeur usuel des avances sur subvention, à confirmer avec la banque.
A10: Poste | B10: T1 2027 | C10: T2 2027 | D10: T3 2027 | E10: T4 2027 | F10: T1 2028 | G10: T2 2028 | H10: T3 2028 | I10: T4 2028 | J10: T1 2029 | K10: T2 2029 | L10: T3 2029 | M10: T4 2029 | N10: T1 2030 | O10: T2 2030 | P10: T3 2030 | Q10: T4 2030 | R10: T1 2031 | S10: T2 2031 | T10: T3 2031 | U10: T4 2031 | V10: Total | W10: Base de calcul
A11: ENCAISSEMENTS
A12: Refacturation au fonds — 0,20 ETP et moyens matériels | B12: 0 | C12: 0 | D12: =(Ressources!C10+Ressources!C11)/2 -> 3502.8 | E12: =(Ressources!C10+Ressources!C11)/2 -> 3502.8 | F12: =(Ressources!D10+Ressources!D11)/4 -> 3280.7 | G12: =(Ressources!D10+Ressources!D11)/4 -> 3280.7 | H12: =(Ressources!D10+Ressources!D11)/4 -> 3280.7 | I12: =(Ressources!D10+Ressources!D11)/4 -> 3280.7 | J12: =(Ressources!E10+Ressources!E11)/4 -> 3342.272 | K12: =(Ressources!E10+Ressources!E11)/4 -> 3342.272 | L12: =(Ressources!E10+Ressources!E11)/4 -> 3342.272 | M12: =(Ressources!E10+Ressources!E11)/4 -> 3342.272 | N12: 0 | O12: 0 | P12: 0 | Q12: 0 | R12: 0 | S12: 0 | T12: 0 | U12: 0 | V12: =SUM(B12:U12) -> 33497.488 | W12: Facturée chaque mois sur convention, réglée dans le trimestre. Apportée directement par le fonds : hors aide publique.
A13: Refacturation à Mare Services — 0,20 ETP et moyens matériels | B13: 0 | C13: 0 | D13: =(Ressources!C12+Ressources!C13)/2 -> 3502.8 | E13: =(Ressources!C12+Ressources!C13)/2 -> 3502.8 | F13: =(Ressources!D12+Ressources!D13)/4 -> 3280.7 | G13: =(Ressources!D12+Ressources!D13)/4 -> 3280.7 | H13: =(Ressources!D12+Ressources!D13)/4 -> 3280.7 | I13: =(Ressources!D12+Ressources!D13)/4 -> 3280.7 | J13: =(Ressources!E12+Ressources!E13)/4 -> 3342.272 | K13: =(Ressources!E12+Ressources!E13)/4 -> 3342.272 | L13: =(Ressources!E12+Ressources!E13)/4 -> 3342.272 | M13: =(Ressources!E12+Ressources!E13)/4 -> 3342.272 | N13: 0 | O13: 0 | P13: 0 | Q13: 0 | R13: 0 | S13: 0 | T13: 0 | U13: 0 | V13: =SUM(B13:U13) -> 33497.488 | W13: Idem, réglée par Mare Services. Hors aide publique.
A14: Reste à charge versé par le fonds (bloc B.3) | B14: =(Ressources!C14)/4 -> 3831.1877 | C14: =(Ressources!C14)/4 -> 3831.1877 | D14: =(Ressources!C14)/4 -> 3831.1877 | E14: =(Ressources!C14)/4 -> 3831.1877 | F14: =(Ressources!D14)/4 -> 5526.1946 | G14: =(Ressources!D14)/4 -> 5526.1946 | H14: =(Ressources!D14)/4 -> 5526.1946 | I14: =(Ressources!D14)/4 -> 5526.1946 | J14: =(Ressources!E14)/4 -> 8016.7423 | K14: =(Ressources!E14)/4 -> 8016.7423 | L14: =(Ressources!E14)/4 -> 8016.7423 | M14: =(Ressources!E14)/4 -> 8016.7423 | N14: 0 | O14: 0 | P14: 0 | Q14: 0 | R14: 0 | S14: 0 | T14: 0 | U14: 0 | V14: =SUM(B14:U14) -> 69496.498 | W14: Versé par quarts en début de trimestre, comme au planning financier du fonds.
A15: Autofinancement — cotisations des membres | B15: =Ressources!C15 -> 625.07 | C15: 0 | D15: 0 | E15: 0 | F15: =Ressources!D15 -> 1083.39 | G15: 0 | H15: 0 | I15: 0 | J15: =Ressources!E15 -> 1195.7244 | K15: 0 | L15: 0 | M15: 0 | N15: 0 | O15: 0 | P15: 0 | Q15: 0 | R15: 0 | S15: 0 | T15: 0 | U15: 0 | V15: =SUM(B15:U15) -> 2904.1844 | W15: Appelées au premier trimestre de chaque exercice.
A16: Aide FEAMPA versée | B16: =IF(COLUMN()-COLUMN($B$36)>=$B$5,OFFSET(B36,0,-$B$5),0) -> 0 | C16: =IF(COLUMN()-COLUMN($B$36)>=$B$5,OFFSET(C36,0,-$B$5),0) -> 0 | D16: =IF(COLUMN()-COLUMN($B$36)>=$B$5,OFFSET(D36,0,-$B$5),0) -> 0 | E16: =IF(COLUMN()-COLUMN($B$36)>=$B$5,OFFSET(E36,0,-$B$5),0) -> 0 | F16: =IF(COLUMN()-COLUMN($B$36)>=$B$5,OFFSET(F36,0,-$B$5),0) -> 0 | G16: =IF(COLUMN()-COLUMN($B$36)>=$B$5,OFFSET(G36,0,-$B$5),0) -> 0 | H16: =IF(COLUMN()-COLUMN($B$36)>=$B$5,OFFSET(H36,0,-$B$5),0) -> 0 | I16: =IF(COLUMN()-COLUMN($B$36)>=$B$5,OFFSET(I36,0,-$B$5),0) -> 0 | ... U16: =IF(COLUMN()-COLUMN($B$36)>=$B$5,OFFSET(U36,0,-$B$5),0) -> 29785.785 | V16: =SUM(B16:U16) -> 151022.78 | W16: Versement de la demande de paiement du semestre, décalé du délai fixé en B5.
A17: TOTAL DES ENCAISSEMENTS | B17: =SUM(B12:B16) -> 4456.2577 | C17: =SUM(C12:C16) -> 3831.1877 | D17: =SUM(D12:D16) -> 10836.788 | E17: =SUM(E12:E16) -> 10836.788 | F17: =SUM(F12:F16) -> 13170.985 | G17: =SUM(G12:G16) -> 12087.595 | H17: =SUM(H12:H16) -> 12087.595 | I17: =SUM(I12:I16) -> 12087.595 | ... U17: =SUM(U12:U16) -> 29785.785 | V17: =SUM(B17:U17) -> 290418.44
A18: DÉCAISSEMENTS
A19: Charges de personnel (salaires et cotisations) | B19: 0 | C19: 0 | D19: =(Dépenses!C7)/2 -> 14415 | E19: =(Dépenses!C7)/2 -> 14415 | F19: =(Dépenses!D7)/4 -> 14695.5 | G19: =(Dépenses!D7)/4 -> 14695.5 | H19: =(Dépenses!D7)/4 -> 14695.5 | I19: =(Dépenses!D7)/4 -> 14695.5 | J19: =(Dépenses!E7)/4 -> 14981.61 | K19: =(Dépenses!E7)/4 -> 14981.61 | L19: =(Dépenses!E7)/4 -> 14981.61 | M19: =(Dépenses!E7)/4 -> 14981.61 | N19: 0 | O19: 0 | P19: 0 | Q19: 0 | R19: 0 | S19: 0 | T19: 0 | U19: 0 | V19: =SUM(B19:U19) -> 147538.44 | W19: Chef de projet recruté au 1er juillet 2027.
A20: Prestations externes | B20: =N(Hypothèses!C43) -> 230 | C20: 0 | D20: =(Dépenses!C13-N(Hypothèses!C43))/2 -> 8557.5 | E20: =(Dépenses!C13-N(Hypothèses!C43))/2 -> 8557.5 | F20: =(Dépenses!D13)/4 -> 6728.75 | G20: =(Dépenses!D13)/4 -> 6728.75 | H20: =(Dépenses!D13)/4 -> 6728.75 | I20: =(Dépenses!D13)/4 -> 6728.75 | J20: =(Dépenses!E13)/4 -> 6728.75 | K20: =(Dépenses!E13)/4 -> 6728.75 | L20: =(Dépenses!E13)/4 -> 6728.75 | M20: =(Dépenses!E13)/4 -> 6728.75 | N20: 0 | O20: 0 | P20: 0 | Q20: 0 | R20: 0 | S20: 0 | T20: 0 | U20: 0 | V20: =SUM(B20:U20) -> 71175 | W20: Formalités de création au T1 2027 ; le reste au fil des trimestres.
A21: Déplacements et missions | B21: 0 | C21: 0 | D21: =(Dépenses!C17)/2 -> 3795 | E21: =(Dépenses!C17)/2 -> 3795 | F21: =(Dépenses!D17)/4 -> 2670 | G21: =(Dépenses!D17)/4 -> 2670 | H21: =(Dépenses!D17)/4 -> 2670 | I21: =(Dépenses!D17)/4 -> 2670 | J21: =(Dépenses!E17)/4 -> 2670 | K21: =(Dépenses!E17)/4 -> 2670 | L21: =(Dépenses!E17)/4 -> 2670 | M21: =(Dépenses!E17)/4 -> 2670 | N21: 0 | O21: 0 | P21: 0 | Q21: 0 | R21: 0 | S21: 0 | T21: 0 | U21: 0 | V21: =SUM(B21:U21) -> 28950
A22: Animation et concertation | B22: 0 | C22: 0 | D22: =(Dépenses!C21)/2 -> 600 | E22: =(Dépenses!C21)/2 -> 600 | F22: =(Dépenses!D21)/4 -> 262.5 | G22: =(Dépenses!D21)/4 -> 262.5 | H22: =(Dépenses!D21)/4 -> 262.5 | I22: =(Dépenses!D21)/4 -> 262.5 | J22: =(Dépenses!E21)/4 -> 262.5 | K22: =(Dépenses!E21)/4 -> 262.5 | L22: =(Dépenses!E21)/4 -> 262.5 | M22: =(Dépenses!E21)/4 -> 262.5 | N22: 0 | O22: 0 | P22: 0 | Q22: 0 | R22: 0 | S22: 0 | T22: 0 | U22: 0 | V22: =SUM(B22:U22) -> 3300
A23: Frais généraux (hors frais financiers) | B23: 0 | C23: 0 | D23: =(Dépenses!C30-Dépenses!C29)/2 -> 3659 | E23: =(Dépenses!C30-Dépenses!C29)/2 -> 3659 | F23: =(Dépenses!D30-Dépenses!D29)/4 -> 1990.5 | G23: =(Dépenses!D30-Dépenses!D29)/4 -> 1990.5 | H23: =(Dépenses!D30-Dépenses!D29)/4 -> 1990.5 | I23: =(Dépenses!D30-Dépenses!D29)/4 -> 1990.5 | J23: =(Dépenses!E30-Dépenses!E29)/4 -> 2014.75 | K23: =(Dépenses!E30-Dépenses!E29)/4 -> 2014.75 | L23: =(Dépenses!E30-Dépenses!E29)/4 -> 2014.75 | M23: =(Dépenses!E30-Dépenses!E29)/4 -> 2014.75 | N23: 0 | O23: 0 | P23: 0 | Q23: 0 | R23: 0 | S23: 0 | T23: 0 | U23: 0 | V23: =SUM(B23:U23) -> 23339
A24: Intérêts de l'avance Crédit Maritime | B24: =0 -> 0 | C24: =B32*$B$7/4 -> 9.6717787 | D24: =C32*$B$7/4 -> 0 | E24: =D32*$B$7/4 -> 214.27423 | F24: =E32*$B$7/4 -> 469.32407 | G24: =F32*$B$7/4 -> 639.89393 | H24: =G32*$B$7/4 -> 826.1383 | I24: =H32*$B$7/4 -> 1014.7107 | J24: =I32*$B$7/4 -> 1205.6403 | ... U24: =T32*$B$7/4 -> 367.72467 | V24: =SUM(B24:U24) -> 16115.913 | W24: Encours de fin du trimestre précédent × taux annuel ÷ 4.
A25: TOTAL DES DÉCAISSEMENTS | B25: =SUM(B19:B24) -> 230 | C25: =SUM(C19:C24) -> 9.6717787 | D25: =SUM(D19:D24) -> 31026.5 | E25: =SUM(E19:E24) -> 31240.774 | F25: =SUM(F19:F24) -> 26816.574 | G25: =SUM(G19:G24) -> 26987.144 | H25: =SUM(H19:H24) -> 27173.388 | I25: =SUM(I19:I24) -> 27361.961 | ... U25: =SUM(U19:U24) -> 367.72467 | V25: =SUM(B25:U25) -> 290418.35
A27: Solde du trimestre avant avance | B27: =B17-B25 -> 4226.2577 | C27: =C17-C25 -> 3821.5159 | D27: =D17-D25 -> -20189.712 | E27: =E17-E25 -> -20403.987 | F27: =F17-F25 -> -13645.589 | G27: =G17-G25 -> -14899.549 | H27: =H17-H25 -> -15085.794 | I27: =I17-I25 -> -15274.366 | ... U27: =U17-U25 -> 29418.061 | V27: =SUM(B27:U27) -> 0.086617461
A28: Trésorerie avant avance | B28: =B27 -> 4226.2577 | C28: =B33+C27 -> 8821.5159 | D28: =C33+D27 -> -12141.939 | E28: =D33+E27 -> -15403.987 | F28: =E33+F27 -> -8645.5895 | G28: =F33+G27 -> -9899.5494 | H28: =G33+H27 -> -10085.794 | I28: =H33+I27 -> -10274.366 | J28: =I33+J27 -> -6966.2396 | ... U28: =T33+U27 -> 29418.061
A29: AVANCE DE TRÉSORERIE — CRÉDIT MARITIME
A30: Tirage sur l'avance | B30: =MAX(0,$B$6-B28) -> 773.7423 | C30: =MAX(0,$B$6-C28) -> 0 | D30: =MAX(0,$B$6-D28) -> 17141.939 | E30: =MAX(0,$B$6-E28) -> 20403.987 | F30: =MAX(0,$B$6-F28) -> 13645.589 | G30: =MAX(0,$B$6-G28) -> 14899.549 | H30: =MAX(0,$B$6-H28) -> 15085.794 | I30: =MAX(0,$B$6-I28) -> 15274.366 | ... M30: =MAX(0,$B$6-M28) -> 0 | N30: =MAX(0,0-N28) -> 0 | O30: =MAX(0,0-O28) -> 0 | P30: =MAX(0,0-P28) -> 1058.9764 | Q30: =MAX(0,0-Q28) -> 0 | R30: =MAX(0,0-R28) -> 717.45861 | S30: =MAX(0,0-S28) -> 0 | T30: =MAX(0,0-T28) -> 363.18486 | U30: =MAX(0,0-U28) -> 0 | V30: =SUM(B30:U30) -> 138120.3 | W30: Tiré dès que la trésorerie passerait sous le plancher de sécurité (plancher levé en 2030, fin de l'opération).
A31: Remboursement de l'avance | B31: =0 -> 0 | C31: =MIN(B32,MAX(0,C28-$B$6)) -> 773.7423 | D31: =MIN(C32,MAX(0,D28-$B$6)) -> 0 | E31: =MIN(D32,MAX(0,E28-$B$6)) -> 0 | F31: =MIN(E32,MAX(0,F28-$B$6)) -> 0 | G31: =MIN(F32,MAX(0,G28-$B$6)) -> 0 | H31: =MIN(G32,MAX(0,H28-$B$6)) -> 0 | I31: =MIN(H32,MAX(0,I28-$B$6)) -> 0 | J31: =MIN(I32,MAX(0,J28-$B$6)) -> 0 | ... M31: =MIN(L32,MAX(0,M28-$B$6)) -> 18899.569 | N31: =MIN(M32,MAX(0,N28-0)) -> 3546.1578 | O31: =MIN(N32,MAX(0,O28-0)) -> 28043.101 | P31: =MIN(O32,MAX(0,P28-0)) -> 0 | Q31: =MIN(P32,MAX(0,Q28-0)) -> 28380.402 | R31: =MIN(Q32,MAX(0,R28-0)) -> 0 | S31: =MIN(R32,MAX(0,S28-0)) -> 29059.358 | T31: =MIN(S32,MAX(0,T28-0)) -> 0 | U31: =MIN(T32,MAX(0,U28-0)) -> 29417.974 | V31: =SUM(B31:U31) -> 138120.3 | W31: Remboursé dès que la trésorerie dépasse le plancher, en pratique à chaque versement FEAMPA.
A32: Encours de l'avance en fin de trimestre | B32: =B30-B31 -> 773.7423 | C32: =B32+C30-C31 -> 0 | D32: =C32+D30-D31 -> 17141.939 | E32: =D32+E30-E31 -> 37545.925 | F32: =E32+F30-F31 -> 51191.515 | G32: =F32+G30-G31 -> 66091.064 | H32: =G32+H30-H31 -> 81176.858 | I32: =H32+I30-I31 -> 96451.224 | J32: =I32+J30-J31 -> 108417.46 | ... U32: =T32+U30-U31 -> 0
A33: Trésorerie en fin de trimestre | B33: =B28+B30-B31 -> 5000 | C33: =C28+C30-C31 -> 8047.7736 | D33: =D28+D30-D31 -> 5000 | E33: =E28+E30-E31 -> 5000 | F33: =F28+F30-F31 -> 5000 | G33: =G28+G30-G31 -> 5000 | H33: =H28+H30-H31 -> 5000 | I33: =I28+I30-I31 -> 5000 | ... U33: =U28+U30-U31 -> 0.086617461
A35: SUIVI DES DEMANDES DE PAIEMENT FEAMPA
A36: Aide acquise sur les dépenses du semestre (demande de paiement) | B36: 0 | C36: 0 | D36: 0 | E36: =Ressources!C8 -> 32545.979 | F36: 0 | G36: =Ressources!D8/2 -> 29452.616 | H36: 0 | I36: =Ressources!D8/2 -> 29452.616 | J36: 0 | K36: =Ressources!E8/2 -> 29785.785 | L36: 0 | M36: =Ressources!E8/2 -> 29785.785 | N36: 0 | O36: 0 | P36: 0 | Q36: 0 | R36: 0 | S36: 0 | T36: 0 | U36: 0 | V36: =SUM(B36:U36) -> 151022.78 | W36: Demande déposée à la fin de chaque semestre, sur factures acquittées. 2027 : toute l'activité est au second semestre.
A37: Aide FEAMPA restant à percevoir (fin de trimestre) | B37: =B36-B16 -> 0 | C37: =B37+C36-C16 -> 0 | D37: =C37+D36-D16 -> 0 | E37: =D37+E36-E16 -> 32545.979 | F37: =E37+F36-F16 -> 32545.979 | G37: =F37+G36-G16 -> 61998.595 | H37: =G37+H36-H16 -> 61998.595 | I37: =H37+I36-I16 -> 91451.211 | J37: =I37+J36-J16 -> 91451.211 | ... U37: =T37+U36-U16 -> 0
A39: INDICATEURS ET CONTRÔLES
A40: Avance maximale mobilisée — montant à demander au Crédit Maritime | B40: =MAX(B32:U32) -> 135206.94
A41: Plafond indicatif de l'avance (quotité × aide FEAMPA notifiée) | B41: =B8*Ressources!F8 -> 120818.23
A42: Contrôle — avance sous le plafond | B42: =IF(B40<=B41,"ok","DÉPASSEMENT") -> DÉPASSEMENT
A43: Intérêts calculés sur la période (2027-2031) | B43: =SUM(B24:U24) -> 16115.913
A44: Intérêts inscrits au budget (Dépenses, ligne 28) | B44: =Dépenses!F29 -> 16116 | C44: Si le contrôle signale un écart, recopier les intérêts annuels de la ligne 24 dans Hypothèses (ligne « Intérêts de l'avance »).
A45: Contrôle — intérêts budgétés = intérêts calculés (à 10 € près) | B45: =IF(ABS(B43-B44)<10,"ok","À METTRE À JOUR") -> ok
...
