Workbook

Sheet Planning financier
A1: PLANNING FINANCIER 2026-2029 — FONDS DE DOTATION MARE DURABILIS
A2: Trimestre par trimestre. Chaque montant provient d'une slide de la note stratégique v1, du budget SmartSnap déposé, ou d'un calendrier fourni par le porteur (onglet « Sources »).
A3: Trois levées de fonds, calculées : la première finance les engagements de 2026 — Mare Collect, étude de conception du chalutier — et les moyens communs et le fonctionnement de 2026 et 2027 ; la deuxième amorce les programmes et porte Mare Collect 2027-2029 et les blocs B et C de 2028-2029 ; la troisième couvre le chalutier et la fin de période. La dotation est non consomptible : seuls ses produits financent.
B5: T1 2026 | C5: T2 2026 | D5: T3 2026 | E5: T4 2026 | F5: T1 2027 | G5: T2 2027 | H5: T3 2027 | I5: T4 2027 | J5: T1 2028 | K5: T2 2028 | L5: T3 2028 | M5: T4 2028 | N5: T1 2029 | O5: T2 2029 | P5: T3 2029 | Q5: T4 2029 | R5: Total planifié | S5: Enveloppe de référence | T5: Reste à dater | U5: Source et calendrier
A6: 1. ENGAGEMENTS — BLOC A · ENVELOPPES DE PROGRAMME
A7: P1 · Cocktail chimique du Rhône | G7: 150000 | K7: 150000 | O7: 150000 | R7: =SUM(B7:Q7) -> 450000 | S7: 450000 | T7: =S7-R7 -> 0 | U7: Slide 1.3 : 3 × 150 000 €. Calendrier : T2 2027, T2 2028, T2 2029 (porteur).
A8: P2 · Fishwind | H8: 800000 | R8: =SUM(B8:Q8) -> 800000 | S8: 800000 | T8: =S8-R8 -> 0 | U8: Slide 1.3 : 800 000 €. Calendrier : T3 2027 (porteur).
A9: P3 · Mare Collect | E9: 43000 | I9: 43000 | M9: 43000 | Q9: 43000 | R9: =SUM(B9:Q9) -> 172000 | S9: 172000 | T9: =S9-R9 -> 0 | U9: Note stratégique : 4 × 43 000 €. Calendrier : T4 2026, T4 2027, T4 2028, T4 2029 (porteur).
A10: P4 · Étude de conception du chalutier | E10: 70000 | R10: =SUM(B10:Q10) -> 70000 | S10: 70000 | T10: =S10-R10 -> 0 | U10: Slide 1.3 : 70 000 €. Calendrier : T4 2026 (porteur).
A11: P4 · Construction du chalutier | L11: 2000000 | R11: =SUM(B11:Q11) -> 2000000 | S11: 2000000 | T11: =S11-R11 -> 0 | U11: Slide 1.3 : 2 000 000 €. Calendrier : T3 2028 (porteur).
A12: P4 · SmartSnap — tranches 2027 à 2029 | F12: 108350 | J12: 48350 | N12: 67850 | R12: =SUM(B12:Q12) -> 224550 | S12: 423250 | T12: =S12-R12 -> 198700 | U12: Budget SmartSnap déposé, annexe 4 : 108 350 / 48 350 / 67 850 € pour les années 1 à 3. Projet démarré le 01/01/2027, base annuelle : tranche placée au T1 de chaque exercice.
A13: Sous-total bloc A | B13: =B7+B8+B9+B10+B11+B12 -> 0 | C13: =C7+C8+C9+C10+C11+C12 -> 0 | D13: =D7+D8+D9+D10+D11+D12 -> 0 | E13: =E7+E8+E9+E10+E11+E12 -> 113000 | F13: =F7+F8+F9+F10+F11+F12 -> 108350 | G13: =G7+G8+G9+G10+G11+G12 -> 150000 | H13: =H7+H8+H9+H10+H11+H12 -> 800000 | I13: =I7+I8+I9+I10+I11+I12 -> 43000 | ... Q13: =Q7+Q8+Q9+Q10+Q11+Q12 -> 43000 | R13: =SUM(B13:Q13) -> 3716550 | S13: =S7+S8+S9+S10+S11+S12 -> 3915250 | T13: =T7+T8+T9+T10+T11+T12 -> 198700
A14: Mémo · SmartSnap années 4 et 5 (2030-2031), hors horizon du planning | R14: 198700 | U14: Budget SmartSnap : 106 850 € (2030) + 91 850 € (2031). Engagés au titre de la même convention mais décaissés après la période.
A16: 2. ENGAGEMENTS — BLOC B · MOYENS COMMUNS
A17: B.1 · Plateforme Mare Services — apport de démarrage et charges | E17: 0 | I17: 188.49 | M17: 6276.72 | Q17: 6517.17 | R17: =SUM(B17:Q17) -> 12982.38 | S17: 0 | T17: =S17-R17 -> -12982.38 | U17: Aucune charge en 2026 (plateforme créée en 2027). La commission (7 120 €) ne couvre pas les charges : outils 600 €/an, Stripe 33 €/an, refacturation par l'association de 0,20 ETP du chef de projet (coût complet) et de 20 % des moyens matériels, frais de constitution de 400 € en 2027. Déficit couvert : 919 € en 2027 (T4), 6 636 € en 2028, 6 882 € en 2029.
A18: B.2 · Structure de détention du matériel — apport de démarrage | E18: 2120 | R18: =SUM(B18:Q18) -> 2120 | S18: =S17 -> 0 | T18: =T17 -> -12982.38 | U18: Apport de démarrage 2 120 € : dépôt des statuts 400 €, assurance RC 400 €, comptabilité 1 200 €, frais bancaires 120 €. Aucun achat d'équipement prévu.
A19: B.3 · Reste à charge de la part non publique — association Mare Durabilis | B19: 0 | C19: 0 | D19: 0 | E19: 0 | F19: ='Circuit public'!C21/4 -> 2379.684 | G19: ='Circuit public'!C21/4 -> 2379.684 | H19: ='Circuit public'!C21/4 -> 2379.684 | I19: ='Circuit public'!C21/4 -> 2379.684 | J19: ='Circuit public'!D21/4 -> 4846.7008 | K19: ='Circuit public'!D21/4 -> 4846.7008 | L19: ='Circuit public'!D21/4 -> 4846.7008 | M19: ='Circuit public'!D21/4 -> 4846.7008 | N19: ='Circuit public'!E21/4 -> 7174.7776 | O19: ='Circuit public'!E21/4 -> 7174.7776 | P19: ='Circuit public'!E21/4 -> 7174.7776 | Q19: ='Circuit public'!E21/4 -> 7174.7776 | R19: =SUM(B19:Q19) -> 57604.649 | U19: Reste à charge de l'association après financement public (80 % de l'assiette éligible), refacturations et autofinancement (1 %), y compris les intérêts de l'avance de trésorerie ; repris de l'onglet Circuit public, réparti par quart.
A20: Sous-total bloc B | B20: =SUM(B17:B19) -> 0 | C20: =SUM(C17:C19) -> 0 | D20: =SUM(D17:D19) -> 0 | E20: =SUM(E17:E19) -> 2120 | F20: =SUM(F17:F19) -> 2379.684 | G20: =SUM(G17:G19) -> 2379.684 | H20: =SUM(H17:H19) -> 2379.684 | I20: =SUM(I17:I19) -> 2568.1739 | ... Q20: =SUM(Q17:Q19) -> 13691.948 | R20: =SUM(B20:Q20) -> 72707.03
A21: 3. ENGAGEMENTS — BLOC C · FRAIS DE FONCTIONNEMENT DU FONDS
A22: Quote-part du chef de projet refacturée | H22: ='Circuit public'!C18/2 -> 2842.8307 | I22: ='Circuit public'!C18/2 -> 2842.8307 | J22: ='Circuit public'!D18/4 -> 2899.6873 | K22: ='Circuit public'!D18/4 -> 2899.6873 | L22: ='Circuit public'!D18/4 -> 2899.6873 | M22: ='Circuit public'!D18/4 -> 2899.6873 | N22: ='Circuit public'!E18/4 -> 2957.6811 | O22: ='Circuit public'!E18/4 -> 2957.6811 | P22: ='Circuit public'!E18/4 -> 2957.6811 | Q22: ='Circuit public'!E18/4 -> 2957.6811 | R22: =SUM(B22:Q22) -> 29115.135 | U22: Budget de fonctionnement ASSO, onglet Ressources ligne 10 : 5 766 / 11 756 / 11 985 € (20 % du coût complet du chef de projet : salaire chargé, base 55 000 € en 2026, plus mutuelle et prévoyance). 2027 porté sur T3-T4 (recrutement au 1er juillet 2027) ; 2028 et 2029 par quart.
A23: Honoraires du commissaire aux comptes | B23: 0 | C23: 0 | D23: 0 | E23: 0 | G23: 8000 | K23: 8000 | O23: 8000 | R23: =SUM(B23:Q23) -> 24000 | U23: Slide 3.4 : 6 000 €/an de 2027 à 2029
A24: Expertise comptable et tenue des comptes | B24: 0 | C24: 0 | D24: 0 | E24: 0 | I24: 3000 | M24: 4000 | Q24: 6000 | R24: =SUM(B24:Q24) -> 13000 | U24: Slide 3.4 : 1 500 € (2027) puis 2 000 €/an
A25: Honoraires juridiques et fiscaux propres au fonds | B25: 0 | C25: 0 | D25: 0 | E25: 0 | F25: 0 | G25: 0 | H25: 0 | I25: 0 | J25: 15000 | N25: 15000 | R25: =SUM(B25:Q25) -> 30000 | U25: Slide 3.4 : 3 000 €/an en 2028 et 2029
A26: Frais bancaires et gestion des placements | E26: 300 | F26: 125 | G26: 125 | H26: 125 | I26: 125 | J26: 250 | K26: 250 | L26: 250 | M26: 250 | N26: 250 | O26: 250 | P26: 250 | Q26: 250 | R26: =SUM(B26:Q26) -> 2800 | U26: Slide 3.4 : 300 € (2026, à compter de la création en septembre) puis 500 €/an.
A27: Frais de recherche de fonds | B27: 0 | C27: 0 | D27: 0 | E27: 0 | F27: 0 | G27: 0 | H27: 0 | I27: 0 | J27: 2500 | K27: 2500 | L27: 2500 | M27: 2500 | N27: 2500 | O27: 2500 | P27: 2500 | Q27: 2500 | R27: =SUM(B27:Q27) -> 20000 | U27: Slide 3.4 : 2 500 €/an en 2028 et 2029, réparti par quart.
A28: Quote-part des moyens matériels refacturée par l'association | B28: 0 | C28: 0 | D28: 0 | E28: 0 | F28: ='Circuit public'!C19/4 -> 147.4571 | G28: ='Circuit public'!C19/4 -> 147.4571 | H28: ='Circuit public'!C19/4 -> 147.4571 | I28: ='Circuit public'!C19/4 -> 147.4571 | J28: ='Circuit public'!D19/4 -> 291.24207 | K28: ='Circuit public'!D19/4 -> 291.24207 | L28: ='Circuit public'!D19/4 -> 291.24207 | M28: ='Circuit public'!D19/4 -> 291.24207 | N28: ='Circuit public'!E19/4 -> 293.3615 | O28: ='Circuit public'!E19/4 -> 293.3615 | P28: ='Circuit public'!E19/4 -> 293.3615 | Q28: ='Circuit public'!E19/4 -> 293.3615 | R28: =SUM(B28:Q28) -> 2928.2427 | U28: 20 % des charges locatives, multirisque, télécommunications et fournitures courantes de l'association (hors locaux et mobilier, portés par le fonds).
A29: Locaux mis à disposition de l'association (loyer, TEOM, charges) | B29: 0 | C29: 0 | D29: 0 | E29: 0 | F29: 0 | G29: 0 | H29: 2175 | I29: 2175 | J29: 2253 | K29: 2253 | L29: 2253 | M29: 2253 | N29: 2256.5 | O29: 2256.5 | P29: 2256.5 | Q29: 2256.5 | R29: =SUM(B29:Q29) -> 22388 | U29: Transféré du budget de l'association : bail porté par le fonds (700 €/mois), bureau mis à disposition par convention. 4 350 € (2027, six mois), 9 012 €, 9 026 € avec TEOM et charges.
A30: Mobilier de première installation | B30: 0 | C30: 0 | D30: 0 | E30: 0 | F30: 0 | G30: 0 | H30: 10000 | I30: 0 | J30: 0 | K30: 0 | L30: 0 | M30: 0 | N30: 0 | O30: 0 | P30: 0 | Q30: 0 | R30: =SUM(B30:Q30) -> 10000 | U30: Mobilier de première installation, 10 000 € au T3 2027 (transféré du budget de l'association).
A31: Frais de représentation (réceptions de partenaires et de mécènes) | B31: 0 | C31: 0 | D31: 0 | E31: 0 | F31: 0 | G31: 0 | H31: 100 | I31: 100 | J31: 25 | K31: 25 | L31: 25 | M31: 25 | N31: 25 | O31: 25 | P31: 25 | Q31: 25 | R31: =SUM(B31:Q31) -> 400 | U31: Transféré du budget de l'association (non éligible au FEAMPA) : 200 € en 2027 (T3-T4), 100 €/an ensuite.
A32: Sous-total bloc C | B32: =B22+B23+B24+B25+B26+B27+B28+B29+B30+B31 -> 0 | C32: =C22+C23+C24+C25+C26+C27+C28+C29+C30+C31 -> 0 | D32: =D22+D23+D24+D25+D26+D27+D28+D29+D30+D31 -> 0 | E32: =E22+E23+E24+E25+E26+E27+E28+E29+E30+E31 -> 300 | F32: =F22+F23+F24+F25+F26+F27+F28+F29+F30+F31 -> 272.4571 | G32: =G22+G23+G24+G25+G26+G27+G28+G29+G30+G31 -> 8272.4571 | H32: =H22+H23+H24+H25+H26+H27+H28+H29+H30+H31 -> 15390.288 | I32: =I22+I23+I24+I25+I26+I27+I28+I29+I30+I31 -> 8390.2878 | ... Q32: =Q22+Q23+Q24+Q25+Q26+Q27+Q28+Q29+Q30+Q31 -> 14282.543 | R32: =SUM(B32:Q32) -> 154631.38 | U32: Cumul recalculé : 154 242 € sur la période (budget pluriannuel FDD bloc C).
A34: TOTAL ENGAGÉ (A + B + C) | B34: =B13+B20+B32 -> 0 | C34: =C13+C20+C32 -> 0 | D34: =D13+D20+D32 -> 0 | E34: =E13+E20+E32 -> 115420 | F34: =F13+F20+F32 -> 111002.14 | G34: =G13+G20+G32 -> 160652.14 | H34: =H13+H20+H32 -> 817769.97 | I34: =I13+I20+I32 -> 53958.462 | ... Q34: =Q13+Q20+Q32 -> 70974.49 | R34: =SUM(B34:Q34) -> 3943888.4
A35: Engagements cumulés | B35: =B34 -> 0 | C35: =B35+C34 -> 0 | D35: =C35+D34 -> 0 | E35: =D35+E34 -> 115420 | F35: =E35+F34 -> 226422.14 | G35: =F35+G34 -> 387074.28 | H35: =G35+H34 -> 1204844.3 | I35: =H35+I34 -> 1258802.7 | J35: =I35+J34 -> 1335218.3 | ... Q35: =P35+Q34 -> 3943888.4
A37: 4. DOTATION NON CONSOMPTIBLE — capital inaliénable, seuls les produits sont mobilisables
A38: Versements à la dotation | D38: 15000 | E38: 0 | F38: 15000 | I38: 15000 | R38: =SUM(B38:Q38) -> 45000 | U38: Dotation initiale de 45 000 € : 15 000 € apportés par la SATHOAN au T4 2026 à la constitution du fonds, 15 000 € par le CRPMEM au T1 2027, 15 000 € par l’OP du Sud au T4 2027.
A39: Capital de dotation cumulé | B39: =B38 -> 0 | C39: =B39+C38 -> 0 | D39: =C39+D38 -> 15000 | E39: =D39+E38 -> 15000 | F39: =E39+F38 -> 30000 | G39: =F39+G38 -> 30000 | H39: =G39+H38 -> 30000 | I39: =H39+I38 -> 45000 | J39: =I39+J38 -> 45000 | ... Q39: =P39+Q38 -> 45000 | U39: Non consomptible : ce capital ne finance aucun engagement. Il n'entre pas dans les encaissements mobilisables.
A40: Produits financiers de la dotation | B40: 0 | C40: =B39*$B$67/4 -> 0 | D40: =C39*$B$67/4 -> 0 | E40: =D39*$B$67/4 -> 75 | F40: =E39*$B$67/4 -> 75 | G40: =F39*$B$67/4 -> 150 | H40: =G39*$B$67/4 -> 150 | I40: =H39*$B$67/4 -> 150 | J40: =I39*$B$67/4 -> 225 | ... Q40: =P39*$B$67/4 -> 225 | R40: =SUM(B40:Q40) -> 2400 | U40: Rendement annuel de 2 % (hypothèse porteur), appliqué au capital placé au trimestre précédent. Slide 3.4 : ressource du bloc C.
A42: 5. RESSOURCES MOBILISABLES DU FONDS — circuit privé
A43: Levée 1 — amorçage : Mare Collect 2026, étude de conception du chalutier, moyens communs et fonctionnement 2026-2027 | E43: =E9+E10+SUM(B20:I20)+SUM(B32:I32) -> 157452.72 | R43: =SUM(B43:Q43) -> 157452.72 | U43: Encaissée au T4 2026, trimestre des premiers engagements. Finance la première tranche Mare Collect (43 000 €), l'étude de conception du chalutier (70 000 €) et les blocs B et C des exercices 2026 et 2027. Montant calculé.
A44: Levée 2 — amorçage des programmes P1, P2 et SmartSnap ; Mare Collect 2027-2029 ; moyens communs et fonctionnement 2028-2029 | F44: =MAX(0,K35-SUM(B40:K40)-R43)+SUM(L20:Q20)+SUM(L32:Q32)+M9+Q9 -> 1567535.7 | R44: =SUM(B44:Q44) -> 1567535.7 | U44: Encaissée au T1 2027, trimestre de la première tranche SmartSnap. Couvre les engagements jusqu'au T2 2028 inclus, nets de la levée 1 et des produits financiers, auxquels s'ajoutent les tranches Mare Collect 2028 et 2029 et les blocs B et C du T3 2028 au T4 2029.
A45: Levée 3 — financement du chalutier et fin de période | K45: =MAX(0,Q35-SUM(B40:Q40)-R43-R44) -> 2216500 | R45: =SUM(B45:Q45) -> 2216500 | U45: Encaissée au T2 2028, un trimestre avant l'engagement du chalutier. Solde du besoin de la période : chalutier, dernières tranches P1 et SmartSnap.
...

Sheet Synthèse annuelle
A1: SYNTHÈSE ANNUELLE — à reporter sur la slide « Planning financier »
B3: 2026 | C3: 2027 | D3: 2028 | E3: 2029 | F3: Total
A4: Engagé — bloc A · programmes | B4: =SUM('Planning financier'!B13:E13) -> 113000 | C4: =SUM('Planning financier'!F13:I13) -> 1101350 | D4: =SUM('Planning financier'!J13:M13) -> 2241350 | E4: =SUM('Planning financier'!N13:Q13) -> 260850 | F4: =SUM(B4:E4) -> 3716550
A5: Engagé — bloc B · moyens communs | B5: =SUM('Planning financier'!B20:E20) -> 2120 | C5: =SUM('Planning financier'!F20:I20) -> 9707.2258 | D5: =SUM('Planning financier'!J20:M20) -> 25663.523 | E5: =SUM('Planning financier'!N20:Q20) -> 35216.28 | F5: =SUM(B5:E5) -> 72707.03
A6: Engagé — bloc C · fonctionnement | B6: =SUM('Planning financier'!B32:E32) -> 300 | C6: =SUM('Planning financier'!F32:I32) -> 32325.49 | D6: =SUM('Planning financier'!J32:M32) -> 59875.718 | E6: =SUM('Planning financier'!N32:Q32) -> 62130.17 | F6: =SUM(B6:E6) -> 154631.38
A7: TOTAL ENGAGÉ | B7: =SUM('Planning financier'!B34:E34) -> 115420 | C7: =SUM('Planning financier'!F34:I34) -> 1143382.7 | D7: =SUM('Planning financier'!J34:M34) -> 2326889.2 | E7: =SUM('Planning financier'!N34:Q34) -> 358196.45 | F7: =SUM(B7:E7) -> 3943888.4
A9: Levée 1 | B9: =SUM('Planning financier'!B43:E43) -> 157452.72 | C9: =SUM('Planning financier'!F43:I43) -> 0 | D9: =SUM('Planning financier'!J43:M43) -> 0 | E9: =SUM('Planning financier'!N43:Q43) -> 0 | F9: =SUM(B9:E9) -> 157452.72
A10: Levée 2 | B10: =SUM('Planning financier'!B44:E44) -> 0 | C10: =SUM('Planning financier'!F44:I44) -> 1567535.7 | D10: =SUM('Planning financier'!J44:M44) -> 0 | E10: =SUM('Planning financier'!N44:Q44) -> 0 | F10: =SUM(B10:E10) -> 1567535.7
A11: Levée 3 | B11: =SUM('Planning financier'!B45:E45) -> 0 | C11: =SUM('Planning financier'!F45:I45) -> 0 | D11: =SUM('Planning financier'!J45:M45) -> 2216500 | E11: =SUM('Planning financier'!N45:Q45) -> 0 | F11: =SUM(B11:E11) -> 2216500
A12: Produits de la dotation | B12: =SUM('Planning financier'!B46:E46) -> 75 | C12: =SUM('Planning financier'!F46:I46) -> 525 | D12: =SUM('Planning financier'!J46:M46) -> 900 | E12: =SUM('Planning financier'!N46:Q46) -> 900 | F12: =SUM(B12:E12) -> 2400
A13: TOTAL ENCAISSÉ MOBILISABLE | B13: =SUM('Planning financier'!B49:E49) -> 157527.72 | C13: =SUM('Planning financier'!F49:I49) -> 1568060.7 | D13: =SUM('Planning financier'!J49:M49) -> 2217400 | E13: =SUM('Planning financier'!N49:Q49) -> 900 | F13: =SUM(B13:E13) -> 3943888.4
A15: Versements à la dotation (non consomptible) | B15: =SUM('Planning financier'!B38:E38) -> 15000 | C15: =SUM('Planning financier'!F38:I38) -> 30000 | D15: =SUM('Planning financier'!J38:M38) -> 0 | E15: =SUM('Planning financier'!N38:Q38) -> 0 | F15: =SUM(B15:E15) -> 45000
A16: Capital de dotation en fin d'exercice | B16: ='Planning financier'!E39 -> 15000 | C16: ='Planning financier'!I39 -> 45000 | D16: ='Planning financier'!M39 -> 45000 | E16: ='Planning financier'!Q39 -> 45000 | F16: ='Planning financier'!Q39 -> 45000
A18: Couverture cumulée en fin d'exercice | B18: ='Planning financier'!E53 -> 42107.716 | C18: ='Planning financier'!I53 -> 466785.69 | D18: ='Planning financier'!M53 -> 357296.45 | E18: ='Planning financier'!Q53 -> 0
A20: CONTRÔLES DE COHÉRENCE
A21: Bloc C attendu (budget pluriannuel FDD, onglet « C · Fonctionnement ») | B21: 300 | C21: 32325.49 | D21: 59875.72 | E21: 62130.17 | F21: =SUM(B21:E21) -> 154631.38
A22: Écart bloc C (doit être nul) | B22: =B21-B6 -> 0 | C22: =C21-C6 -> 0.0002 | D22: =D21-D6 -> 0.0024 | E22: =E21-E6 -> -0.0003 | F22: =F21-F6 -> 0.0023
A24: Enveloppe des programmes — note stratégique (Mare Collect 4 × 43 000 €, étude de conception 70 000 €) | F24: 3915200
A25: Enveloppe des programmes — après budget SmartSnap déposé (423 250 €) | F25: 3915250
A26: Programmes datés sur 2026-2029 | F26: =F4 -> 3716550
A27: Fishwind — daté au T3 2027 | F27: 0
A28: SmartSnap — tranches 2030-2031, hors horizon | F28: 198700
A29: Contrôle (doit être nul) | F29: =F25-F26-F27-F28 -> 0
A31: Besoin de mécénat couvert par les trois levées | F31: =F9+F10+F11 -> 3941488.4
A32: Part de l'enveloppe non financée par les levées (hors horizon) | F32: =F28 -> 198700

Sheet Circuit public
A1: CIRCUIT PUBLIC — BUDGET DE FONCTIONNEMENT DE L'ASSOCIATION MARE DURABILIS
A2: Hors trésorerie du fonds de dotation. Repris du classeur « Mare Durabilis — Budget de fonctionnement 2026-2029 (ASSO) », onglets Dépenses, Ressources et Synthèse. Valeurs recopiées : modifier le budget ASSO, puis reporter ici.
B4: 2026 | C4: 2027 | D4: 2028 | E4: 2029 | F4: Total
B5: PRÉFIGURATION | C5: OUVERTURE | D5: RÉGIME DE CROISIÈRE | E5: RECONDUCTION
A6: DÉPENSES DE FONCTIONNEMENT DE LA GOUVERNANCE
A7: Charges de personnel | B7: 0 | C7: 28428.307 | D7: 57993.747 | E7: 59153.622 | F7: =SUM(B7:E7) -> 145575.68
A8: dont chef de projet — coût total employeur (salaire, cotisations, mutuelle, prévoyance) | B8: 0 | C8: 28428.307 | D8: 57993.747 | E8: 59153.622 | F8: =SUM(B8:E8) -> 145575.68
A9: dont protection sociale complémentaire — incluse dans la ligne précédente | B9: 0 | C9: 0 | D9: 0 | E9: 0 | F9: =SUM(B9:E9) -> 0
A10: Prestations externes (juridique, ingénierie, études, communication) | B10: 0 | C10: 16123.8 | D10: 25866.904 | E10: 25883.942 | F10: =SUM(B10:E10) -> 67874.646
A11: Déplacements et missions | B11: 0 | C11: 3544 | D11: 7088 | E11: 7088 | F11: =SUM(B11:E11) -> 17720
A12: Animation et concertation | B12: 0 | C12: 286.76 | D12: 528.92 | E12: 534.428 | F12: =SUM(B12:E12) -> 1350.108
A13: Frais généraux et financiers (hors locaux et mobilier, portés par le fonds) | B13: 0 | C13: 3815.942 | D13: 9557.9614 | E13: 18968.04 | F13: =SUM(B13:E13) -> 32341.944
A14: TOTAL DES DÉPENSES DE L'ASSOCIATION | B14: =B7+B10+B11+B12+B13 -> 0 | C14: =C7+C10+C11+C12+C13 -> 52198.809 | D14: =D7+D10+D11+D12+D13 -> 101035.53 | E14: =E7+E10+E11+E12+E13 -> 111628.03 | F14: =SUM(B14:E14) -> 264862.37
A16: RESSOURCES
A17: Part FEAMPA (80 % de l'assiette éligible : salaire à 0,60 ETP + forfaits de 15 % et de 6,3 % + dépenses directes) | B17: 0 | C17: 29607.106 | D17: 55110.938 | E17: 55804.301 | F17: =SUM(B17:E17) -> 140522.34
A18: Refacturation au fonds — quote-part du chef de projet (0,20 ETP) | B18: 0 | C18: 5685.6614 | D18: 11598.749 | E18: 11830.724 | F18: =SUM(B18:E18) -> 29115.135
A19: Refacturation au fonds — quote-part des moyens matériels (20 %) | B19: 0 | C19: 589.8284 | D19: 1164.9683 | E19: 1173.446 | F19: =SUM(B19:E19) -> 2928.2427
A20: Refacturation à Mare Services — 0,20 ETP du chef de projet et 20 % des moyens matériels | B20: 0 | C20: 6275.4898 | D20: 12763.718 | E20: 13004.17 | F20: =SUM(B20:E20) -> 32043.378
A21: Reste à charge de la part non publique — versé par le fonds (bloc B.3) | B21: 0 | C21: 9518.7358 | D21: 19386.803 | E21: 28699.11 | F21: =SUM(B21:E21) -> 57604.649
A22: Autofinancement de l'association (1 % des dépenses) | B22: 0 | C22: 521.9881 | D22: 1010.3553 | E22: 1116.2803 | F22: =SUM(B22:E22) -> 2648.6237
A23: TOTAL DES RESSOURCES | B23: =SUM(B17:B22) -> 0 | C23: =SUM(C17:C22) -> 52198.809 | D23: =SUM(D17:D22) -> 101035.53 | E23: =SUM(E17:E22) -> 111628.03 | F23: =SUM(B23:E23) -> 264862.37
A24: Contrôle — écart ressources / dépenses (doit être nul) | B24: =B23-B14 -> 0 | C24: =C23-C14 -> -0.0001 | D24: =D23-D14 -> 0 | E24: =E23-E14 -> -9.999999e-05 | F24: =SUM(B24:E24) -> -0.00019999999
A26: Taux de financement public | B26: =IFERROR(B17/B14,0) -> 0 | C26: =IFERROR(C17/C14,0) -> 0.56719887 | D26: =IFERROR(D17/D14,0) -> 0.54546096 | E26: =IFERROR(E17/E14,0) -> 0.49991297 | F26: =IFERROR(F17/F14,0) -> 0.53054854
A27: Part portée par le fonds de dotation | B27: =IFERROR((B18+B19+B21)/B14,0) -> 0 | C27: =IFERROR((C18+C19+C21)/C14,0) -> 0.30257827 | D27: =IFERROR((D18+D19+D21)/D14,0) -> 0.31821004 | E27: =IFERROR((E18+E19+E21)/E14,0) -> 0.37359147 | F27: =IFERROR((F18+F19+F21)/F14,0) -> 0.33847023
A29: • 2026 est à zéro : l'association est créée en janvier 2027, aucune charge de fonctionnement n'est portée avant.
A30: • Le chef de projet est recruté au 1er juillet 2027 : le salaire 2027 correspond à six mois d'activité.
A31: • Trois refacturations rémunèrent un service rendu, sur convention de prestation et facture : au fonds, 0,20 ETP et 20 % des moyens matériels ; à Mare Services, 0,20 ETP. Le reste à charge de la part non publique (bloc B.3) couvre ce que ni le financement public, ni les refacturations, ni l'autofinancement ne portent.
A32: • L'autofinancement de l'association est fixé à 1 % de ses dépenses ; le fonds porte le solde de la part non publique (15 % du budget avec ses refacturations).
A33: • Un fonds de dotation ne peut recevoir de fonds publics : la part FEAMPA n'entre jamais dans la trésorerie du fonds.
A34: • Point ouvert : le FEAMPA ferme en 2027. Le relais Région Occitanie / État reste à identifier.
A35: • Point ouvert : certains financeurs exigent une part minimale d'autofinancement du bénéficiaire. À vérifier avant dépôt.
C36: 59100 | D36: 58722 | E36: 59866 | F36: =SUM(B34:E34) -> 0
C37: 53500 | D37: 47322 | E37: 48166 | F37: =SUM(B35:E35) -> 0
C38: 5600 | D38: 11400 | E38: 11700 | F38: =SUM(B36:E36) -> 177688
